Workbook

Sheet Start Here
A1: Local SEO Client Tracker
A2: One copy per client. Work top to bottom: Basic stage first, Advanced only if you can't crack the top 3 after a few weeks.
B4: How to use this tracker
B5: Yellow cells | C5: Fill these in. Everything else is calculated or a label.
B6: Dropdowns | C6: Status, Yes/No and Stage cells have dropdown lists.
B7: Grey italic rows | C7: Example rows showing the expected format. Overwrite them with real data.
B8: Checklist tab | C8: Every task from the workflow. Set Status as you go; progress below updates itself.
B10: Client details
B11: Field | C11: Value | D11: Format / example
B12: Client / business name | D12: e.g. Springfield Plumbing Co (exactly as on the GBP)
B13: Client contact name | D13: e.g. Andrew
B14: Website URL | D14: e.g. springfieldplumbing.com.au
B15: Google Business Profile link | D15: Maps share link
B16: Main keyword | D16: e.g. plumber springfield (confirm with the client)
B17: City / main service area | D17: e.g. Springfield
B18: Primary GBP category | D18: e.g. Plumber
B19: Start date | D19: Date of week 1, e.g. 13/10/2026
B20: Leadsnap heatmap link | D20: app.leadsnap.com report link
B21: GMB Everywhere scan link | D21: Local scan for the main keyword
B22: Website access working? | D22: Yes / No (onboarding email asks for this)
B23: GBP manager access working? | D23: Yes / No
B24: Current stage | C24: Basic | D24: Basic / Advanced
B25: Indexed pages target | C25: 30 | D25: Workflow minimum is 30; raise it for tough markets
B26: Current week of program | C26: =IF(C19="","",MAX(1,MIN(12,INT((TODAY()-C19)/7)+1))) | D26: Calculated from the start date
B29: Progress by milestone (the workflow checklist)
B30: Milestone | C30: Tasks | D30: Done | E30: N/A | F30: % complete | G30: Status
B31: Benchmark done | C31: =COUNTIF(Checklist!$C$5:$C$200,B31) -> 12 | D31: =COUNTIFS(Checklist!$C$5:$C$200,B31,Checklist!$I$5:$I$200,"Done") -> 0 | E31: =COUNTIFS(Checklist!$C$5:$C$200,B31,Checklist!$I$5:$I$200,"N/A") -> 0 | F31: =IF(C31-E31=0,0,D31/(C31-E31)) -> 0 | G31: =IF(C31-E31=0,"N/A",IF(F31>=1,"Done",IF(D31>0,"In progress","Not started"))) -> Not started
B32: Competitive analysis done | C32: =COUNTIF(Checklist!$C$5:$C$200,B32) -> 2 | D32: =COUNTIFS(Checklist!$C$5:$C$200,B32,Checklist!$I$5:$I$200,"Done") -> 0 | E32: =COUNTIFS(Checklist!$C$5:$C$200,B32,Checklist!$I$5:$I$200,"N/A") -> 0 | F32: =IF(C32-E32=0,0,D32/(C32-E32)) -> 0 | G32: =IF(C32-E32=0,"N/A",IF(F32>=1,"Done",IF(D32>0,"In progress","Not started"))) -> Not started
B33: GBP profile optimised | C33: =COUNTIF(Checklist!$C$5:$C$200,B33) -> 11 | D33: =COUNTIFS(Checklist!$C$5:$C$200,B33,Checklist!$I$5:$I$200,"Done") -> 0 | E33: =COUNTIFS(Checklist!$C$5:$C$200,B33,Checklist!$I$5:$I$200,"N/A") -> 0 | F33: =IF(C33-E33=0,0,D33/(C33-E33)) -> 0 | G33: =IF(C33-E33=0,"N/A",IF(F33>=1,"Done",IF(D33>0,"In progress","Not started"))) -> Not started
B34: On-page SEO basic done | C34: =COUNTIF(Checklist!$C$5:$C$200,B34) -> 5 | D34: =COUNTIFS(Checklist!$C$5:$C$200,B34,Checklist!$I$5:$I$200,"Done") -> 0 | E34: =COUNTIFS(Checklist!$C$5:$C$200,B34,Checklist!$I$5:$I$200,"N/A") -> 0 | F34: =IF(C34-E34=0,0,D34/(C34-E34)) -> 0 | G34: =IF(C34-E34=0,"N/A",IF(F34>=1,"Done",IF(D34>0,"In progress","Not started"))) -> Not started
B35: Citations basic done | C35: =COUNTIF(Checklist!$C$5:$C$200,B35) -> 5 | D35: =COUNTIFS(Checklist!$C$5:$C$200,B35,Checklist!$I$5:$I$200,"Done") -> 0 | E35: =COUNTIFS(Checklist!$C$5:$C$200,B35,Checklist!$I$5:$I$200,"N/A") -> 0 | F35: =IF(C35-E35=0,0,D35/(C35-E35)) -> 0 | G35: =IF(C35-E35=0,"N/A",IF(F35>=1,"Done",IF(D35>0,"In progress","Not started"))) -> Not started
B36: On-page SEO advanced done | C36: =COUNTIF(Checklist!$C$5:$C$200,B36) -> 11 | D36: =COUNTIFS(Checklist!$C$5:$C$200,B36,Checklist!$I$5:$I$200,"Done") -> 0 | E36: =COUNTIFS(Checklist!$C$5:$C$200,B36,Checklist!$I$5:$I$200,"N/A") -> 0 | F36: =IF(C36-E36=0,0,D36/(C36-E36)) -> 0 | G36: =IF(C36-E36=0,"N/A",IF(F36>=1,"Done",IF(D36>0,"In progress","Not started"))) -> Not started
B37: Citations advanced done | C37: =COUNTIF(Checklist!$C$5:$C$200,B37) -> 5 | D37: =COUNTIFS(Checklist!$C$5:$C$200,B37,Checklist!$I$5:$I$200,"Done") -> 0 | E37: =COUNTIFS(Checklist!$C$5:$C$200,B37,Checklist!$I$5:$I$200,"N/A") -> 0 | F37: =IF(C37-E37=0,0,D37/(C37-E37)) -> 0 | G37: =IF(C37-E37=0,"N/A",IF(F37>=1,"Done",IF(D37>0,"In progress","Not started"))) -> Not started
B38: Weekly schedule running | C38: =COUNTIF(Checklist!$C$5:$C$200,B38) -> 8 | D38: =COUNTIFS(Checklist!$C$5:$C$200,B38,Checklist!$I$5:$I$200,"Done") -> 0 | E38: =COUNTIFS(Checklist!$C$5:$C$200,B38,Checklist!$I$5:$I$200,"N/A") -> 0 | F38: =IF(C38-E38=0,0,D38/(C38-E38)) -> 0 | G38: =IF(C38-E38=0,"N/A",IF(F38>=1,"Done",IF(D38>0,"In progress","Not started"))) -> Not started
B40: Basic stage | C40: =COUNTIF(Checklist!$E$5:$E$200,"Basic") -> 43 | D40: =COUNTIFS(Checklist!$E$5:$E$200,"Basic",Checklist!$I$5:$I$200,"Done") -> 0 | E40: =COUNTIFS(Checklist!$E$5:$E$200,"Basic",Checklist!$I$5:$I$200,"N/A") -> 0 | F40: =IF(C40-E40=0,0,D40/(C40-E40)) -> 0 | G40: =IF(C40-E40=0,"N/A",IF(F40>=1,"Done",IF(D40>0,"In progress","Not started"))) -> Not started
B41: Advanced stage | C41: =COUNTIF(Checklist!$E$5:$E$200,"Advanced") -> 16 | D41: =COUNTIFS(Checklist!$E$5:$E$200,"Advanced",Checklist!$I$5:$I$200,"Done") -> 0 | E41: =COUNTIFS(Checklist!$E$5:$E$200,"Advanced",Checklist!$I$5:$I$200,"N/A") -> 0 | F41: =IF(C41-E41=0,0,D41/(C41-E41)) -> 0 | G41: =IF(C41-E41=0,"N/A",IF(F41>=1,"Done",IF(D41>0,"In progress","Not started"))) -> Not started
B42: All tasks | C42: =COUNTIF(Checklist!$E$5:$E$200,"*") -> 59 | D42: =COUNTIFS(Checklist!$E$5:$E$200,"*",Checklist!$I$5:$I$200,"Done") -> 0 | E42: =COUNTIFS(Checklist!$E$5:$E$200,"*",Checklist!$I$5:$I$200,"N/A") -> 0 | F42: =IF(C42-E42=0,0,D42/(C42-E42)) -> 0 | G42: =IF(C42-E42=0,"N/A",IF(F42>=1,"Done",IF(D42>0,"In progress","Not started"))) -> Not started
B48: Quick health check
B49: Check | C49: Result | D49: Where
B50: Reviews vs top 3 | C50: =Benchmark!F29 | D50: Benchmark tab
...

Sheet Checklist
A1: Checklist
A2: Every step of the local SEO workflow. Skip ADVANCED tasks on the first run through.
A4: # | B4: Week | C4: Milestone | D4: Section | E4: Stage | F4: Task | G4: How to / standard | H4: Tool or link | I4: Status | J4: Date done | K4: Owner | L4: Notes
A5: 1 | B5: 1 | C5: Benchmark done | D5: Onboarding | E5: Basic | F5: Confirm website access works | G5: The onboarding email asks for it. Ask for a user/admin login in your own name rather than the client's password, and never store passwords in this sheet. Check you can edit pages, titles and the footer. | I5: Not started
A6: 2 | B6: 1 | C6: Benchmark done | D6: Onboarding | E6: Basic | F6: Confirm GBP manager access works | G6: Client adds you as a Manager (they stay Owner). You should be able to open Edit profile. | H6: business.google.com | I6: Not started
A7: 3 | B7: 1 | C7: Benchmark done | D7: Onboarding | E7: Basic | F7: Add client to Leadsnap | G7: Create the business in Leadsnap so you can run heatmaps. | H7: https://app.leadsnap.com/ | I7: Not started
A8: 4 | B8: 1 | C8: Benchmark done | D8: Benchmarking | E8: Basic | F8: Run heatmap on the main keyword | G8: Save the report link and a screenshot. This is the starting point you compare against in week 11–12. Log it on the Benchmark tab. | H8: https://app.leadsnap.com/ | I8: Not started
A9: 5 | B9: 1 | C9: Benchmark done | D9: Benchmarking | E9: Basic | F9: Record reviews and photos for the top 10 | G9: Leadsnap shows reviews and photos for the top-ranking businesses. If the client is way behind, tell them to get reviews and photos coming. | H9: Benchmark tab | I9: Not started
A10: 6 | B10: 1 | C10: Benchmark done | D10: Benchmarking | E10: Basic | F10: Check the top 10 for obvious blackhat / fake listings | G10: Keyword-stuffed names, all caps, odd addresses (e.g. a tree surgeon in a shopping mall), websites with no address. | H10: Blackhat tab | I10: Not started
A11: 7 | B11: 1 | C11: Benchmark done | D11: Website easy wins | E11: Basic | F11: NAP visible on the site and matching the GBP | G11: Business name, address and phone visible on the page and identical to the GBP. | H11: Website Audit tab | I11: Not started
A12: 8 | B12: 1 | C12: Benchmark done | D12: Website easy wins | E12: Basic | F12: Title tag contains main keyword + city | G12: Hover over the browser tab to see the title. Missing keyword or city = easy win. | H12: Website Audit tab | I12: Not started
A13: 9 | B13: 1 | C13: Benchmark done | D13: Website easy wins | E13: Basic | F13: Count indexed pages (site: search) | G13: Google site:theirdomain.com, then Tools to see the result count. At least 30 pages; more in competitive markets. | H13: google.com | I13: Not started
A14: 10 | B14: 1 | C14: Benchmark done | D14: Website easy wins | E14: Basic | F14: Check for LocalBusiness schema | G14: Paste the site into the validator. No local business schema = easy win. | H14: https://validator.schema.org/ | I14: Not started
A15: 11 | B15: 1 | C15: Benchmark done | D15: Website easy wins | E15: Basic | F15: Check for an embedded Google map | G15: Is the GBP map embedded on the homepage (or GBP landing page)? | I15: Not started
A16: 12 | B16: 1 | C16: Weekly schedule running | D16: Weekly | E16: Basic | F16: Weekly GBP update / post | G16: Generate with AI, lightly edit, post. | H16: Weekly tab | I16: Not started
A17: 13 | B17: 1 | C17: Weekly schedule running | D17: Weekly | E17: Basic | F17: Weekly pictures with geodata | G17: Real or AI-made, screenshot, add geotags with GeoSetter. Ranking on the outskirts? Geotag those areas. | H17: https://geosetter.de/en/download-en/ | I17: Not started
A18: 14 | B18: 1 | C18: Weekly schedule running | D18: Client management | E18: Basic | F18: Client asks every customer for a review | G18: Steady stream, not bursts. | H18: Weekly tab | I18: Not started
A19: 15 | B19: 1 | C19: Weekly schedule running | D19: Client management | E19: Basic | F19: Client sends new pictures every week | G19: Or posts them on IG / FB and we grab them. | H19: Weekly tab | I19: Not started
A20: 16 | B20: 1 | C20: Weekly schedule running | D20: Client management | E20: Basic | F20: Send the weekly email update | G20: Use the template for the current week. | H20: Emails tab | I20: Not started
A21: 17 | B21: 1 | C21: Benchmark done | D21: Blackhat | E21: Basic | F21: Report fake listings (only when 100% sure) | G21: Suggest an edit → 'Place is closed or not here', add a photo and short explanation. Never report real businesses, and keep reports factual. | H21: Blackhat tab | I21: Not started
A22: 18 | B22: 2 | C22: Competitive analysis done | D22: Competitive analysis | E22: Basic | F22: Choose the MAIN keyword | G22: Usually obvious (plumber + city). If not, ask AI, then confirm with the client. Leadsnap shows search volume and competitiveness. | H22: Leadsnap | I22: Not started
A23: 19 | B23: 2 | C23: Competitive analysis done | D23: Competitive analysis | E23: Basic | F23: Run a GMB Everywhere local scan | G23: Note the top 20's categories, number of services, profile features and attributes. Log the averages on the GBP tab. | H23: GMB Everywhere | I23: Not started
A24: 20 | B24: 2 | C24: GBP profile optimised | D24: Google Business Profile | E24: Basic | F24: Business name matches the real-life business name | G24: Leave it alone. Only touch this once every other option is exhausted. | H24: GBP → Edit profile | I24: Not started
A25: 21 | B25: 2 | C25: GBP profile optimised | D25: Google Business Profile | E25: Basic | F25: Trim categories to 1 primary + 0–3 secondary | G25: Check the top 20's average in GMB Everywhere (usually about 2). Remove overlapping categories and ones that drift from what you want to rank for. | H25: GBP tab | I25: Not started
A26: 22 | B26: 2 | C26: GBP profile optimised | D26: Google Business Profile | E26: Basic | F26: Hit at least 3 of 5 profile features | G26: Full address, website, phone number. Easy 4th: online appointments linked to the Contact page. | H26: GBP tab | I26: Not started
A27: 23 | B27: 2 | C27: GBP profile optimised | D27: Google Business Profile | E27: Basic | F27: Compile the full services list | G27: GMB Everywhere category finder → related services, or copy services from the top 10 into one document. | H27: https://app.gmbeverywhere.com/release7/category-tool/category-finder.html | I27: Not started
... A35: 31 | B35: 5 | C35: On-page SEO basic done | D35: On-page SEO | E35: Basic | F35: Rewrite the title tag | G35: BEST + primary category + city + business name + primary services + near me. Aim for ~200 characters max. | H35: Website Audit tab | I35: Not started
A36: 32 | B36: 5 | C36: On-page SEO basic done | D36: On-page SEO | E36: Basic | F36: Set the H1 = primary category + city | G36: One H1 per page. | I36: Not started
A37: 33 | B37: 5 | C37: On-page SEO basic done | D37: On-page SEO | E37: Basic | F37: Set H2s to secondary categories + main services | G37: Use the services found with GMB Everywhere. | I37: Not started
A38: 34 | B38: 5 | C38: On-page SEO basic done | D38: On-page SEO | E38: Basic | F38: Add NAP to the footer on every page | G38: Identical to the GBP. Also on the homepage / GBP landing page. | I38: Not started
A39: 35 | B39: 5 | C39: On-page SEO basic done | D39: On-page SEO | E39: Basic | F39: Embed the GBP map on the homepage | G39: GBP / Maps → Share → Embed a map. | I39: Not started
A40: 36 | B40: 6 | C40: On-page SEO advanced done | D40: On-page SEO | E40: Advanced | F40: Add LocalBusiness schema | G40: Generate it, add it to the site, then re-test in the validator. | H40: https://technicalseo.com/tools/schema-markup-generator/ | I40: Not started
A41: 37 | B41: 6 | C41: On-page SEO advanced done | D41: Content | E41: Advanced | F41: Inventory what Google has indexed | G41: List current pages on the Content Plan tab. | H41: Content Plan tab | I41: Not started
A42: 38 | B42: 6 | C42: On-page SEO advanced done | D42: Content | E42: Advanced | F42: Plan the page hierarchy | G42: Rank 1 landing page → Rank 2 category + core services → Rank 3 remaining services, interlinked. | H42: Content Plan tab | I42: Not started
A43: 39 | B43: 7 | C43: On-page SEO advanced done | D43: Content | E43: Advanced | F43: Write service pages (1,000–2,000 words each) | G43: Unique copy per service. Use the service page prompt. Add pictures. | H43: Prompts tab | I43: Not started
A44: 40 | B44: 7 | C44: On-page SEO advanced done | D44: Content | E44: Advanced | F44: Add 'Areas we serve' to the navigation | G44: Plus an Areas we serve page. Get client input on the areas (start with ~5). | I44: Not started
A45: 41 | B45: 7 | C45: On-page SEO advanced done | D45: Content | E45: Advanced | F45: Write area pages (1,200–2,200 words each) | G45: Use the hyperlocal area page prompt. Real local detail, never a fake address. | H45: Prompts tab | I45: Not started
A46: 42 | B46: 8 | C46: On-page SEO advanced done | D46: Interlinking | E46: Advanced | F46: Map services to areas | G46: Decide which services make sense for which areas. | H46: Interlinking tab | I46: Not started
A47: 43 | B47: 8 | C47: On-page SEO advanced done | D47: Interlinking | E47: Advanced | F47: Service pages: 2–4 area links + 'We serve these areas' list | G47: 1–3 short sentences mentioning an area, linked. List of 3–5 areas at the bottom. | H47: Interlinking tab | I47: Not started
A48: 44 | B48: 8 | C48: On-page SEO advanced done | D48: Interlinking | E48: Advanced | F48: Area pages: 3–6 service links + 'Services we offer here' | G48: 2–4 sentences mentioning a service, linked. Section with 3–5 service links. | H48: Interlinking tab | I48: Not started
...

Sheet Benchmark
A1: Benchmark
A2: Where the client stands today. Re-run at week 11–12 and compare.
A3: Heatmap runs (Leadsnap)
A4: Run | B4: Keyword | C4: Date | D4: Grid | E4: Avg rank | F4: Top-3 coverage | G4: Report link / screenshot | H4: Notes
A5: Baseline (week 1) | B5: =IF('Start Here'!C16="","",'Start Here'!C16)
A6: Re-run (week 11–12) | B6: =IF('Start Here'!C16="","",'Start Here'!C16)
A7: Extra run
A9: Change in avg rank | B9: =IF(OR(E5="",E6=""),"",E5-E6) | C9: Positive = moved up
A10: Change in top-3 coverage | B10: =IF(OR(F5="",F6=""),"",F6-F5)
A12: Top 10 for the main keyword (from Leadsnap + GMB Everywhere)
A13: Rank | B13: Business name | C13: Reviews | D13: Rating | E13: Photos | F13: # Categories | G13: Primary category | H13: # Services | I13: Profile features /5 | J13: Looks fake? | K13: Red flags / notes
A14: 1 | B14: Smith & Sons Plumbing | C14: 148 | D14: 4.8 | E14: 96 | F14: 2 | G14: Plumber | H14: 31 | I14: 4 | J14: No | K14: e.g. strong profile, posts weekly
A15: 2
A16: 3
A17: 4
A18: 5
A19: 6
A20: 7
A21: 8
A22: 9
A23: 10
A24: Our client | B24: =IF('Start Here'!C12="","Our client",'Start Here'!C12) -> Our client
A27: Gap analysis
A28: Metric | B28: Top-10 average | C28: Top-3 average | D28: Our client | E28: Gap vs top 3 | F28: Verdict
A29: Reviews | B29: =IFERROR(AVERAGE(C14:C23),"") -> 148 | C29: =IFERROR(AVERAGE(C14:C16),"") -> 148 | D29: =IF(C24="","",C24) | E29: =IF(OR(C29="",D29=""),"",C29-D29) | F29: =IF(D29="","",IF(D29>=C29,"On par","Behind: ask client for reviews"))
A30: Photos | B30: =IFERROR(AVERAGE(E14:E23),"") -> 96 | C30: =IFERROR(AVERAGE(E14:E16),"") -> 96 | D30: =IF(E24="","",E24) | E30: =IF(OR(C30="",D30=""),"",C30-D30) | F30: =IF(D30="","",IF(D30>=C30,"On par","Behind: ask client for photos"))
A31: # Categories | B31: =IFERROR(AVERAGE(F14:F23),"") -> 2 | C31: =IFERROR(AVERAGE(F14:F16),"") -> 2 | D31: =IF(F24="","",F24) | E31: =IF(OR(C31="",D31=""),"",C31-D31) | F31: =IF(D31="","",IF(D31>B31+0.5,"Trim categories","OK"))
A32: # Services | B32: =IFERROR(AVERAGE(H14:H23),"") -> 31 | C32: =IFERROR(AVERAGE(H14:H16),"") -> 31 | D32: =IF(H24="","",H24) | E32: =IF(OR(C32="",D32=""),"",C32-D32) | F32: =IF(D32="","",IF(D32>=B32,"OK","Add services"))
A33: Profile features /5 | B33: =IFERROR(AVERAGE(I14:I23),"") -> 4 | C33: =IFERROR(AVERAGE(I14:I16),"") -> 4 | D33: =IF(I24="","",I24) | E33: =IF(OR(C33="",D33=""),"",C33-D33) | F33: =IF(D33="","",IF(D33>=3,"OK","Add features (min 3)"))
A37: Blackhat check
A38: Suspected fake listings | C38: =COUNTIF(J14:J23,"Yes") -> 0 | D38: Log each one on the Blackhat tab before reporting.

Sheet Website Audit
A1: Website Audit
A2: Easy wins on the client's website. Paste what you find; the Result column checks it.
A4: # | B4: Check | C4: What good looks like | D4: What you found | E4: Result | F4: Fix / notes
A5: 1 | B5: NAP visible and matching GBP | C5: Name, address and phone on the page, identical to the GBP | E5: =IF(D5="","",IF(D5="Yes","Pass","Fail: easy win"))
A6: 2 | B6: Title tag (paste it) | C6: Contains primary category + city | E6: =IF(D6="","",IF(AND(ISNUMBER(SEARCH('Start Here'!$C$18,D6)),ISNUMBER(SEARCH('Start Here'!$C$17,D6))),"Pass","Fail: add category + city"))
A7: 3 | B7: Title tag length (characters) | C7: ~200 max with the workflow format | D7: =IF(D6="","",LEN(D6)) | E7: =IF(D6="","",IF(D7<=200,"OK","Too long: trim"))
A8: 4 | B8: H1 (paste it) | C8: Primary category + city | E8: =IF(D8="","",IF(AND(ISNUMBER(SEARCH('Start Here'!$C$18,D8)),ISNUMBER(SEARCH('Start Here'!$C$17,D8))),"Pass","Fail: H1 = category + city"))
A9: 5 | B9: H2s cover secondary categories + main services | C9: Yes / No | E9: =IF(D9="","",IF(D9="Yes","Pass","Fail: rewrite H2s"))
A10: 6 | B10: NAP in footer on every page | C10: Yes / No | E10: =IF(D10="","",IF(D10="Yes","Pass","Fail: add to footer"))
A11: 7 | B11: Indexed pages (site: search count) | C11: At least the target on Start Here (30) | E11: =IF(D11="","",IF(D11>='Start Here'!$C$25,"Pass","Fail: build pages (Advanced)"))
A12: 8 | B12: LocalBusiness schema (validator.schema.org) | C12: Yes / No | E12: =IF(D12="","",IF(D12="Yes","Pass","Fail: add schema"))
A13: 9 | B13: Google map embedded on homepage | C13: Yes / No | E13: =IF(D13="","",IF(D13="Yes","Pass","Fail: embed GBP map"))
B16: Tip: hover over the browser tab to read the title. For the indexed count, Google site:domain.com and open Tools.

Sheet GBP
A1: Google Business Profile
A2: Categories, profile features and completeness. Compare with the top 20 from GMB Everywhere.
B3: Top-20 benchmark (GMB Everywhere)
B4: Metric | C4: Value | E4: Note
B5: Average # categories (top 20) | E5: Usually around 2
B6: Average # services (top 20) | E6: Aim for at least this, ideally ~30+
B7: Top 20 with at least 3/5 profile features | E7: e.g. 19 of 20
B8: Most common primary category
B9: Attributes matter? (most top 10 have none = no)
B11: Categories
B12: Current categories | C12: Keep? | E12: New setup (1 primary + 0–3 secondary)
D13: Primary:
D14: Secondary 1:
D15: Secondary 2:
D16: Secondary 3:
B21: Current count | C21: =COUNTA(B13:B20) -> 0 | D21: New count | E21: =COUNTA(E13:E16)&IF(COUNTA(E13:E16)>4," – too many"," – OK") -> 0 – OK
B23: Profile features (minimum 3 of 5)
B24: Feature (match GMB Everywhere's five) | C24: Done? | E24: Note
B25: Features done | C25: =COUNTIF(C27:C31,"Yes")&" of 5" -> 0 of 5
B26: Status | C26: =IF(COUNTA(C27:C31)=0,"",IF(COUNTIF(C27:C31,"Yes")>=3,"OK","Add features (min 3)"))
B27: Full address (or service area)
B28: Website
B29: Phone number
B30: Online appointments → Contact page
B31: Business hours
B34: Profile completeness
B35: Item | C35: Status | E35: Note
B36: Business name = real-life name (don't change) | E36: Yes / No
B37: Completeness circle fully green | E37: Yes / No
B38: Services added | C38: =Services!C6 -> 1
B39: Top-20 services with descriptions | C39: =Services!C8 -> 1 of 1
B40: Bookings link → Contact page | E40: Yes / No
B41: FAQs added (how many) | E41: number
B42: Photos added this month | E42: number
B43: Business description written | E43: Yes / No

Sheet Services
A1: Services
A2: Master list for the GBP (max 99). Confirm with the client, add to the profile, write descriptions for the top 20.
B4: Services listed | C4: =COUNTA(B12:B110) -> 1 | E4: vs top-20 average: | F4: =IF(GBP!C6="","",GBP!C6)
B5: Over the 99 limit? | C5: =IF(C4>99,"Too many: max 99","OK") -> OK
B6: Added to GBP | C6: =COUNTIF(F12:F110,"Yes") -> 1
B7: Client confirmed | C7: =COUNTIF(E12:E110,"Yes") -> 1
B8: Top 20 with description | C8: =COUNTIFS(G12:G110,"Yes",H12:H110,"<>")&" of "&COUNTIF(G12:G110,"Yes") -> 1 of 1
B9: Descriptions over 300 chars | C9: =COUNTIF(J12:J110,"Too long") -> 0
A11: # | B11: Service | C11: GBP category | D11: Source | E11: Client offers it? | F11: Added to GBP? | G11: Top 20? | H11: Description (300 characters max) | I11: Chars | J11: Length
A12: 1 | B12: Emergency plumbing | C12: Plumber | D12: Competitors | E12: Yes | F12: Yes | G12: Yes | H12: 24/7 emergency plumbing across Springfield for burst pipes, leaks, blocked drains and hot water failures. Licensed plumbers, upfront pricing and fast arrival times. Call any time, day or night. | I12: =IF(H12="","",LEN(H12)) -> 193 | J12: =IF(H12="","",IF(LEN(H12)<=300,"OK","Too long")) -> OK
A13: 2 | I13: =IF(H13="","",LEN(H13)) | J13: =IF(H13="","",IF(LEN(H13)<=300,"OK","Too long"))
A14: 3 | I14: =IF(H14="","",LEN(H14)) | J14: =IF(H14="","",IF(LEN(H14)<=300,"OK","Too long"))
A15: 4 | I15: =IF(H15="","",LEN(H15)) | J15: =IF(H15="","",IF(LEN(H15)<=300,"OK","Too long"))
A16: 5 | I16: =IF(H16="","",LEN(H16)) | J16: =IF(H16="","",IF(LEN(H16)<=300,"OK","Too long"))
A17: 6 | I17: =IF(H17="","",LEN(H17)) | J17: =IF(H17="","",IF(LEN(H17)<=300,"OK","Too long"))
A18: 7 | I18: =IF(H18="","",LEN(H18)) | J18: =IF(H18="","",IF(LEN(H18)<=300,"OK","Too long"))
A19: 8 | I19: =IF(H19="","",LEN(H19)) | J19: =IF(H19="","",IF(LEN(H19)<=300,"OK","Too long"))
A20: 9 | I20: =IF(H20="","",LEN(H20)) | J20: =IF(H20="","",IF(LEN(H20)<=300,"OK","Too long"))
A21: 10 | I21: =IF(H21="","",LEN(H21)) | J21: =IF(H21="","",IF(LEN(H21)<=300,"OK","Too long"))
A22: 11 | I22: =IF(H22="","",LEN(H22)) | J22: =IF(H22="","",IF(LEN(H22)<=300,"OK","Too long"))
A23: 12 | I23: =IF(H23="","",LEN(H23)) | J23: =IF(H23="","",IF(LEN(H23)<=300,"OK","Too long"))
A24: 13 | I24: =IF(H24="","",LEN(H24)) | J24: =IF(H24="","",IF(LEN(H24)<=300,"OK","Too long"))
... A110: 99 | I110: =IF(H110="","",LEN(H110)) | J110: =IF(H110="","",IF(LEN(H110)<=300,"OK","Too long"))

Sheet Content Plan
A1: Content Plan (ADVANCED)
A2: Only if you can't crack the top 3 in a few weeks. Rank 1 landing page → Rank 2 category/core services → Rank 3 remaining services and areas.
A4: Rank | B4: Page type | C4: Page / topic | D4: URL | E4: Primary keyword | F4: Min words | G4: Words | H4: Length | I4: Links to areas | J4: Links to services | K4: Total links | L4: Link rules | M4: Status | N4: Indexed? | O4: Notes
A5: 1 | B5: Landing page | C5: Homepage | H5: =IF(OR(G5="",F5=""),"",IF(G5>=F5,"OK","Too short")) | L5: =IF(K5="","",IF(K5>10,"Too many links",IF(B5="Service page",IF(AND(I5>=2,I5<=4),"OK","Need 2–4 area links"),IF(B5="Area page",IF(AND(J5>=3,J5<=6),"OK","Need 3–6 service links"),"OK"))))
A6: 2 | B6: Category page | C6: Services overview | H6: =IF(OR(G6="",F6=""),"",IF(G6>=F6,"OK","Too short")) | L6: =IF(K6="","",IF(K6>10,"Too many links",IF(B6="Service page",IF(AND(I6>=2,I6<=4),"OK","Need 2–4 area links"),IF(B6="Area page",IF(AND(J6>=3,J6<=6),"OK","Need 3–6 service links"),"OK"))))
A7: 2 | B7: Core service | C7: Core service 1 | F7: 1000 | H7: =IF(OR(G7="",F7=""),"",IF(G7>=F7,"OK","Too short")) | L7: =IF(K7="","",IF(K7>10,"Too many links",IF(B7="Service page",IF(AND(I7>=2,I7<=4),"OK","Need 2–4 area links"),IF(B7="Area page",IF(AND(J7>=3,J7<=6),"OK","Need 3–6 service links"),"OK"))))
A8: 2 | B8: Core service | C8: Core service 2 | F8: 1000 | H8: =IF(OR(G8="",F8=""),"",IF(G8>=F8,"OK","Too short")) | L8: =IF(K8="","",IF(K8>10,"Too many links",IF(B8="Service page",IF(AND(I8>=2,I8<=4),"OK","Need 2–4 area links"),IF(B8="Area page",IF(AND(J8>=3,J8<=6),"OK","Need 3–6 service links"),"OK"))))
A9: 2 | B9: Core service | C9: Core service 3 | F9: 1000 | H9: =IF(OR(G9="",F9=""),"",IF(G9>=F9,"OK","Too short")) | L9: =IF(K9="","",IF(K9>10,"Too many links",IF(B9="Service page",IF(AND(I9>=2,I9<=4),"OK","Need 2–4 area links"),IF(B9="Area page",IF(AND(J9>=3,J9<=6),"OK","Need 3–6 service links"),"OK"))))
A10: 3 | B10: Service page | C10: Service page 1 | F10: 1000 | H10: =IF(OR(G10="",F10=""),"",IF(G10>=F10,"OK","Too short")) | L10: =IF(K10="","",IF(K10>10,"Too many links",IF(B10="Service page",IF(AND(I10>=2,I10<=4),"OK","Need 2–4 area links"),IF(B10="Area page",IF(AND(J10>=3,J10<=6),"OK","Need 3–6 service links"),"OK"))))
A11: 3 | B11: Service page | C11: Service page 2 | F11: 1000 | H11: =IF(OR(G11="",F11=""),"",IF(G11>=F11,"OK","Too short")) | L11: =IF(K11="","",IF(K11>10,"Too many links",IF(B11="Service page",IF(AND(I11>=2,I11<=4),"OK","Need 2–4 area links"),IF(B11="Area page",IF(AND(J11>=3,J11<=6),"OK","Need 3–6 service links"),"OK"))))
A12: 3 | B12: Service page | C12: Service page 3 | F12: 1000 | H12: =IF(OR(G12="",F12=""),"",IF(G12>=F12,"OK","Too short")) | L12: =IF(K12="","",IF(K12>10,"Too many links",IF(B12="Service page",IF(AND(I12>=2,I12<=4),"OK","Need 2–4 area links"),IF(B12="Area page",IF(AND(J12>=3,J12<=6),"OK","Need 3–6 service links"),"OK"))))
A13: 3 | B13: Service page | C13: Service page 4 | F13: 1000 | H13: =IF(OR(G13="",F13=""),"",IF(G13>=F13,"OK","Too short")) | L13: =IF(K13="","",IF(K13>10,"Too many links",IF(B13="Service page",IF(AND(I13>=2,I13<=4),"OK","Need 2–4 area links"),IF(B13="Area page",IF(AND(J13>=3,J13<=6),"OK","Need 3–6 service links"),"OK"))))
A14: 3 | B14: Service page | C14: Service page 5 | F14: 1000 | H14: =IF(OR(G14="",F14=""),"",IF(G14>=F14,"OK","Too short")) | L14: =IF(K14="","",IF(K14>10,"Too many links",IF(B14="Service page",IF(AND(I14>=2,I14<=4),"OK","Need 2–4 area links"),IF(B14="Area page",IF(AND(J14>=3,J14<=6),"OK","Need 3–6 service links"),"OK"))))
A15: 3 | B15: Service page | C15: Service page 6 | F15: 1000 | H15: =IF(OR(G15="",F15=""),"",IF(G15>=F15,"OK","Too short")) | L15: =IF(K15="","",IF(K15>10,"Too many links",IF(B15="Service page",IF(AND(I15>=2,I15<=4),"OK","Need 2–4 area links"),IF(B15="Area page",IF(AND(J15>=3,J15<=6),"OK","Need 3–6 service links"),"OK"))))
A16: 2 | B16: Areas we serve | C16: Areas we serve | H16: =IF(OR(G16="",F16=""),"",IF(G16>=F16,"OK","Too short")) | L16: =IF(K16="","",IF(K16>10,"Too many links",IF(B16="Service page",IF(AND(I16>=2,I16<=4),"OK","Need 2–4 area links"),IF(B16="Area page",IF(AND(J16>=3,J16<=6),"OK","Need 3–6 service links"),"OK"))))
A17: 3 | B17: Area page | C17: Area page 1 | F17: 1200 | H17: =IF(OR(G17="",F17=""),"",IF(G17>=F17,"OK","Too short")) | L17: =IF(K17="","",IF(K17>10,"Too many links",IF(B17="Service page",IF(AND(I17>=2,I17<=4),"OK","Need 2–4 area links"),IF(B17="Area page",IF(AND(J17>=3,J17<=6),"OK","Need 3–6 service links"),"OK"))))
A18: 3 | B18: Area page | C18: Area page 2 | F18: 1200 | H18: =IF(OR(G18="",F18=""),"",IF(G18>=F18,"OK","Too short")) | L18: =IF(K18="","",IF(K18>10,"Too many links",IF(B18="Service page",IF(AND(I18>=2,I18<=4),"OK","Need 2–4 area links"),IF(B18="Area page",IF(AND(J18>=3,J18<=6),"OK","Need 3–6 service links"),"OK"))))
A19: 3 | B19: Area page | C19: Area page 3 | F19: 1200 | H19: =IF(OR(G19="",F19=""),"",IF(G19>=F19,"OK","Too short")) | L19: =IF(K19="","",IF(K19>10,"Too many links",IF(B19="Service page",IF(AND(I19>=2,I19<=4),"OK","Need 2–4 area links"),IF(B19="Area page",IF(AND(J19>=3,J19<=6),"OK","Need 3–6 service links"),"OK"))))
A20: 3 | B20: Area page | C20: Area page 4 | F20: 1200 | H20: =IF(OR(G20="",F20=""),"",IF(G20>=F20,"OK","Too short")) | L20: =IF(K20="","",IF(K20>10,"Too many links",IF(B20="Service page",IF(AND(I20>=2,I20<=4),"OK","Need 2–4 area links"),IF(B20="Area page",IF(AND(J20>=3,J20<=6),"OK","Need 3–6 service links"),"OK"))))
A21: 3 | B21: Area page | C21: Area page 5 | F21: 1200 | H21: =IF(OR(G21="",F21=""),"",IF(G21>=F21,"OK","Too short")) | L21: =IF(K21="","",IF(K21>10,"Too many links",IF(B21="Service page",IF(AND(I21>=2,I21<=4),"OK","Need 2–4 area links"),IF(B21="Area page",IF(AND(J21>=3,J21<=6),"OK","Need 3–6 service links"),"OK"))))
H22: =IF(OR(G22="",F22=""),"",IF(G22>=F22,"OK","Too short")) | L22: =IF(K22="","",IF(K22>10,"Too many links",IF(B22="Service page",IF(AND(I22>=2,I22<=4),"OK","Need 2–4 area links"),IF(B22="Area page",IF(AND(J22>=3,J22<=6),"OK","Need 3–6 service links"),"OK"))))
H23: =IF(OR(G23="",F23=""),"",IF(G23>=F23,"OK","Too short")) | L23: =IF(K23="","",IF(K23>10,"Too many links",IF(B23="Service page",IF(AND(I23>=2,I23<=4),"OK","Need 2–4 area links"),IF(B23="Area page",IF(AND(J23>=3,J23<=6),"OK","Need 3–6 service links"),"OK"))))
H24: =IF(OR(G24="",F24=""),"",IF(G24>=F24,"OK","Too short")) | L24: =IF(K24="","",IF(K24>10,"Too many links",IF(B24="Service page",IF(AND(I24>=2,I24<=4),"OK","Need 2–4 area links"),IF(B24="Area page",IF(AND(J24>=3,J24<=6),"OK","Need 3–6 service links"),"OK"))))
H25: =IF(OR(G25="",F25=""),"",IF(G25>=F25,"OK","Too short")) | L25: =IF(K25="","",IF(K25>10,"Too many links",IF(B25="Service page",IF(AND(I25>=2,I25<=4),"OK","Need 2–4 area links"),IF(B25="Area page",IF(AND(J25>=3,J25<=6),"OK","Need 3–6 service links"),"OK"))))
H26: =IF(OR(G26="",F26=""),"",IF(G26>=F26,"OK","Too short")) | L26: =IF(K26="","",IF(K26>10,"Too many links",IF(B26="Service page",IF(AND(I26>=2,I26<=4),"OK","Need 2–4 area links"),IF(B26="Area page",IF(AND(J26>=3,J26<=6),"OK","Need 3–6 service links"),"OK"))))
H27: =IF(OR(G27="",F27=""),"",IF(G27>=F27,"OK","Too short")) | L27: =IF(K27="","",IF(K27>10,"Too many links",IF(B27="Service page",IF(AND(I27>=2,I27<=4),"OK","Need 2–4 area links"),IF(B27="Area page",IF(AND(J27>=3,J27<=6),"OK","Need 3–6 service links"),"OK"))))
H28: =IF(OR(G28="",F28=""),"",IF(G28>=F28,"OK","Too short")) | L28: =IF(K28="","",IF(K28>10,"Too many links",IF(B28="Service page",IF(AND(I28>=2,I28<=4),"OK","Need 2–4 area links"),IF(B28="Area page",IF(AND(J28>=3,J28<=6),"OK","Need 3–6 service links"),"OK"))))
H29: =IF(OR(G29="",F29=""),"",IF(G29>=F29,"OK","Too short")) | L29: =IF(K29="","",IF(K29>10,"Too many links",IF(B29="Service page",IF(AND(I29>=2,I29<=4),"OK","Need 2–4 area links"),IF(B29="Area page",IF(AND(J29>=3,J29<=6),"OK","Need 3–6 service links"),"OK"))))
H30: =IF(OR(G30="",F30=""),"",IF(G30>=F30,"OK","Too short")) | L30: =IF(K30="","",IF(K30>10,"Too many links",IF(B30="Service page",IF(AND(I30>=2,I30<=4),"OK","Need 2–4 area links"),IF(B30="Area page",IF(AND(J30>=3,J30<=6),"OK","Need 3–6 service links"),"OK"))))
H31: =IF(OR(G31="",F31=""),"",IF(G31>=F31,"OK","Too short")) | L31: =IF(K31="","",IF(K31>10,"Too many links",IF(B31="Service page",IF(AND(I31>=2,I31<=4),"OK","Need 2–4 area links"),IF(B31="Area page",IF(AND(J31>=3,J31<=6),"OK","Need 3–6 service links"),"OK"))))
H32: =IF(OR(G32="",F32=""),"",IF(G32>=F32,"OK","Too short")) | L32: =IF(K32="","",IF(K32>10,"Too many links",IF(B32="Service page",IF(AND(I32>=2,I32<=4),"OK","Need 2–4 area links"),IF(B32="Area page",IF(AND(J32>=3,J32<=6),"OK","Need 3–6 service links"),"OK"))))
H33: =IF(OR(G33="",F33=""),"",IF(G33>=F33,"OK","Too short")) | L33: =IF(K33="","",IF(K33>10,"Too many links",IF(B33="Service page",IF(AND(I33>=2,I33<=4),"OK","Need 2–4 area links"),IF(B33="Area page",IF(AND(J33>=3,J33<=6),"OK","Need 3–6 service links"),"OK"))))
... H36: =IF(OR(G36="",F36=""),"",IF(G36>=F36,"OK","Too short")) | L36: =IF(K36="","",IF(K36>10,"Too many links",IF(B36="Service page",IF(AND(I36>=2,I36<=4),"OK","Need 2–4 area links"),IF(B36="Area page",IF(AND(J36>=3,J36<=6),"OK","Need 3–6 service links"),"OK"))))
C38: Pages planned | D38: =COUNTA(C5:C36) -> 17
C39: Published | D39: =COUNTIF(M5:M36,"Published")+COUNTIF(M5:M36,"Interlinked") -> 0
C40: Indexed | D40: =COUNTIF(N5:N36,"Yes") -> 0

Sheet Interlinking
A1: Interlinking map (ADVANCED)
A2: Put an x where a service makes sense for an area. Service pages link to their areas (2–4); area pages link to their services (3–6).
A4: Service pages ↓ / Area pages → | B4: Area 1 | C4: Area 2 | D4: Area 3 | E4: Area 4 | F4: Area 5 | G4: Area 6 | H4: Area 7 | I4: Area 8 | J4: Area links | K4: Rule (2–4)
A5: Service 1 | J5: =COUNTIF(B5:I5,"x") -> 0 | K5: =IF(J5=0,"",IF(AND(J5>=2,J5<=4),"OK","Need 2–4 area links"))
A6: Service 2 | J6: =COUNTIF(B6:I6,"x") -> 0 | K6: =IF(J6=0,"",IF(AND(J6>=2,J6<=4),"OK","Need 2–4 area links"))
A7: Service 3 | J7: =COUNTIF(B7:I7,"x") -> 0 | K7: =IF(J7=0,"",IF(AND(J7>=2,J7<=4),"OK","Need 2–4 area links"))
A8: Service 4 | J8: =COUNTIF(B8:I8,"x") -> 0 | K8: =IF(J8=0,"",IF(AND(J8>=2,J8<=4),"OK","Need 2–4 area links"))
A9: Service 5 | J9: =COUNTIF(B9:I9,"x") -> 0 | K9: =IF(J9=0,"",IF(AND(J9>=2,J9<=4),"OK","Need 2–4 area links"))
A10: Service 6 | J10: =COUNTIF(B10:I10,"x") -> 0 | K10: =IF(J10=0,"",IF(AND(J10>=2,J10<=4),"OK","Need 2–4 area links"))
A11: Service 7 | J11: =COUNTIF(B11:I11,"x") -> 0 | K11: =IF(J11=0,"",IF(AND(J11>=2,J11<=4),"OK","Need 2–4 area links"))
A12: Service 8 | J12: =COUNTIF(B12:I12,"x") -> 0 | K12: =IF(J12=0,"",IF(AND(J12>=2,J12<=4),"OK","Need 2–4 area links"))
A13: Service 9 | J13: =COUNTIF(B13:I13,"x") -> 0 | K13: =IF(J13=0,"",IF(AND(J13>=2,J13<=4),"OK","Need 2–4 area links"))
A14: Service 10 | J14: =COUNTIF(B14:I14,"x") -> 0 | K14: =IF(J14=0,"",IF(AND(J14>=2,J14<=4),"OK","Need 2–4 area links"))
A15: Service links | B15: =COUNTIF(B5:B14,"x") -> 0 | C15: =COUNTIF(C5:C14,"x") -> 0 | D15: =COUNTIF(D5:D14,"x") -> 0 | E15: =COUNTIF(E5:E14,"x") -> 0 | F15: =COUNTIF(F5:F14,"x") -> 0 | G15: =COUNTIF(G5:G14,"x") -> 0 | H15: =COUNTIF(H5:H14,"x") -> 0 | I15: =COUNTIF(I5:I14,"x") -> 0
A16: Rule (3–6) | B16: =IF(B15=0,"",IF(AND(B15>=3,B15<=6),"OK","Need 3–6")) | C16: =IF(C15=0,"",IF(AND(C15>=3,C15<=6),"OK","Need 3–6")) | D16: =IF(D15=0,"",IF(AND(D15>=3,D15<=6),"OK","Need 3–6")) | E16: =IF(E15=0,"",IF(AND(E15>=3,E15<=6),"OK","Need 3–6")) | F16: =IF(F15=0,"",IF(AND(F15>=3,F15<=6),"OK","Need 3–6")) | G16: =IF(G15=0,"",IF(AND(G15>=3,G15<=6),"OK","Need 3–6")) | H16: =IF(H15=0,"",IF(AND(H15>=3,H15<=6),"OK","Need 3–6")) | I16: =IF(I15=0,"",IF(AND(I15>=3,I15<=6),"OK","Need 3–6"))
A19: Rules
A20: • Only add links that help the reader.
A21: • Max 8–10 links on one page.
A22: • Vary the anchor text: 'our plumbing repair service', 'services in Downtown', 'see bathroom remodel options'.
A23: • Don't put links only in the footer.
A24: • Homepage + contact page: 'Areas we serve' (all areas) and 'Our main services'.
A25: • Every important page needs a few incoming links. Click-test every link.

Sheet Citations
A1: Citations
A2: 80/20 first, then keyword directories, competitor links and the additional sources. NAP must match the website and GBP exactly.
A3: Live | B3: =COUNTIF(F9:F120,"Live") -> 0
A4: 80/20 live (of 4–5) | B4: =COUNTIFS(C9:C120,"80/20",F9:F120,"Live") -> 0
A5: To do | B5: =COUNTIF(F9:F120,"To do") -> 54
A6: Waiting on verification | B6: =COUNTIF(F9:F120,"Awaiting verification") -> 0
A8: Platform | B8: URL | C8: Type | D8: Region | E8: Cost | F8: Status | G8: NAP matches? | H8: Client verifies? | I8: Date live | J8: Notes (never store passwords here)
A9: Bing Places for Business | B9: https://www.bing.com/forbusiness/ | C9: 80/20 | D9: All | F9: To do
A10: Apple Business Connect | B10: https://businessconnect.apple.com | C10: 80/20 | D10: All | F10: To do
A11: Foursquare | B11: https://foursquare.com/products/business-listings/ | C11: 80/20 | D11: All | E11: $20 | F11: To do
A12: Yelp | B12: https://biz.yelp.com/ | C12: 80/20 | D12: All | F12: To do
A13: Data Axle | B13: https://local-listings.data-axle.com/ | C13: 80/20 | D13: US | F13: To do
A14: Directory ranking for keyword #1 | C14: Keyword directory | F14: To do
A15: Directory ranking for keyword #2 | C15: Keyword directory | F15: To do
A16: Competitor link gap #1 | C16: Competitor link | F16: To do
A17: Yellow Pages Australia | B17: https://www.yellowpages.com.au/ | C17: Directory | D17: AU | F17: To do
A18: TrueLocal | B18: https://www.truelocal.com.au/ | C18: Directory | D18: AU | F18: To do
A19: Hotfrog | B19: https://www.hotfrog.com.au/ | C19: Directory | D19: AU | F19: To do
A20: hipages (trades) | B20: https://hipages.com.au/ | C20: Directory | D20: AU | F20: To do
A21: Oneflare | B21: https://www.oneflare.com.au/ | C21: Directory | D21: AU | F21: To do
A22: Yellow NZ | B22: https://yellow.co.nz/ | C22: Directory | D22: NZ | F22: To do
A23: Finda | B23: https://www.finda.co.nz/ | C23: Directory | D23: NZ | F23: To do
A24: NoCowboys (trades) | B24: https://www.nocowboys.co.nz/ | C24: Directory | D24: NZ | F24: To do
A25: Builderscrack (trades) | B25: https://builderscrack.co.nz/ | C25: Directory | D25: NZ | F25: To do
A26: Cortana | C26: Additional source | F26: To do
A27: Alexa | C27: Additional source | F27: To do
A28: Siri | C28: Additional source | F28: To do
A29: Instagram | C29: Additional source | F29: To do
A30: YouTube | C30: Additional source | F30: To do
A31: Twitter / X | C31: Additional source | F31: To do
A32: LinkedIn | C32: Additional source | F32: To do
A33: Facebook | C33: Additional source | F33: To do
A34: Pinterest | C34: Additional source | F34: To do
A35: Yell | C35: Additional source | F35: To do
A36: Nextdoor | C36: Additional source | F36: To do
A37: Waze | C37: Additional source | F37: To do
... A59: Manta | C59: Additional source | F59: To do
A60: Leadsnap citations (paid) | B60: https://app.leadsnap.com/ | C60: Paid | D60: All | E60: $20/mo | F60: To do
A61: Leadforge (paid) | C61: Paid | D61: All | F61: To do
A62: FatJoe (paid) | C62: Paid | D62: All | F62: To do

Sheet Weekly
A1: Weekly schedule
A2: Weekly GBP update, geotagged photos, reviews from the client and the weekly email.
A3: Emails sent | C3: =COUNTIF(E9:E34,"Yes") -> 0
A4: GBP posts done | C4: =COUNTIF(F9:F34,"Yes") -> 0
A5: Photos added | C5: =SUM(G9:G34) -> 0
A6: New reviews | C6: =SUM(I9:I34) -> 0
A8: Week | B8: Starts | C8: Focus | D8: Email to send | E8: Email sent? | F8: GBP post? | G8: Photos added | H8: Geotagged? | I8: New reviews | J8: Total reviews | K8: Notes
A9: 1 | B9: =IF('Start Here'!$C$19="","",'Start Here'!$C$19+0) | C9: Benchmarking | D9: Week 1 email (Emails tab)
A10: 2 | B10: =IF('Start Here'!$C$19="","",'Start Here'!$C$19+7) | C10: Starting on the GBP | D10: Week 2 email (Emails tab)
A11: 3 | B11: =IF('Start Here'!$C$19="","",'Start Here'!$C$19+14) | C11: Completing the GBP | D11: Week 3 email (Emails tab)
A12: 4 | B12: =IF('Start Here'!$C$19="","",'Start Here'!$C$19+21) | C12: GBP overview + what's next | D12: Week 4 email (Emails tab)
A13: 5 | B13: =IF('Start Here'!$C$19="","",'Start Here'!$C$19+28) | C13: On-page SEO basics | D13: Week 5 email (Emails tab)
A14: 6 | B14: =IF('Start Here'!$C$19="","",'Start Here'!$C$19+35) | C14: On-page SEO: content structure inventory | D14: Week 6 email (Emails tab)
A15: 7 | B15: =IF('Start Here'!$C$19="","",'Start Here'!$C$19+42) | C15: On-page SEO: content structure completion | D15: Week 7 email (Emails tab)
A16: 8 | B16: =IF('Start Here'!$C$19="","",'Start Here'!$C$19+49) | C16: On-page SEO overview + what's next | D16: Week 8 email (Emails tab)
A17: 9 | B17: =IF('Start Here'!$C$19="","",'Start Here'!$C$19+56) | C17: Citations start | D17: Week 9 email (Emails tab)
A18: 10 | B18: =IF('Start Here'!$C$19="","",'Start Here'!$C$19+63) | C18: Citations continued | D18: Week 10 email (Emails tab)
A19: 11 | B19: =IF('Start Here'!$C$19="","",'Start Here'!$C$19+70) | C19: Rankings overview | D19: Week 11 email (Emails tab)
A20: 12 | B20: =IF('Start Here'!$C$19="","",'Start Here'!$C$19+77) | C20: Grand overview + prep for sales call | D20: Week 12 email (Emails tab)
A21: 13 | B21: =IF('Start Here'!$C$19="","",'Start Here'!$C$19+84) | C21: Ongoing: weekly post, photos, reviews | D21: Optional monthly update
A22: 14 | B22: =IF('Start Here'!$C$19="","",'Start Here'!$C$19+91) | C22: Ongoing: weekly post, photos, reviews | D22: Optional monthly update
A23: 15 | B23: =IF('Start Here'!$C$19="","",'Start Here'!$C$19+98) | C23: Ongoing: weekly post, photos, reviews | D23: Optional monthly update
A24: 16 | B24: =IF('Start Here'!$C$19="","",'Start Here'!$C$19+105) | C24: Ongoing: weekly post, photos, reviews | D24: Optional monthly update
A25: 17 | B25: =IF('Start Here'!$C$19="","",'Start Here'!$C$19+112) | C25: Ongoing: weekly post, photos, reviews | D25: Optional monthly update
A26: 18 | B26: =IF('Start Here'!$C$19="","",'Start Here'!$C$19+119) | C26: Ongoing: weekly post, photos, reviews | D26: Optional monthly update
A27: 19 | B27: =IF('Start Here'!$C$19="","",'Start Here'!$C$19+126) | C27: Ongoing: weekly post, photos, reviews | D27: Optional monthly update
A28: 20 | B28: =IF('Start Here'!$C$19="","",'Start Here'!$C$19+133) | C28: Ongoing: weekly post, photos, reviews | D28: Optional monthly update
A29: 21 | B29: =IF('Start Here'!$C$19="","",'Start Here'!$C$19+140) | C29: Ongoing: weekly post, photos, reviews | D29: Optional monthly update
A30: 22 | B30: =IF('Start Here'!$C$19="","",'Start Here'!$C$19+147) | C30: Ongoing: weekly post, photos, reviews | D30: Optional monthly update
A31: 23 | B31: =IF('Start Here'!$C$19="","",'Start Here'!$C$19+154) | C31: Ongoing: weekly post, photos, reviews | D31: Optional monthly update
A32: 24 | B32: =IF('Start Here'!$C$19="","",'Start Here'!$C$19+161) | C32: Ongoing: weekly post, photos, reviews | D32: Optional monthly update
A33: 25 | B33: =IF('Start Here'!$C$19="","",'Start Here'!$C$19+168) | C33: Ongoing: weekly post, photos, reviews | D33: Optional monthly update
A34: 26 | B34: =IF('Start Here'!$C$19="","",'Start Here'!$C$19+175) | C34: Ongoing: weekly post, photos, reviews | D34: Optional monthly update

Sheet Emails
A1: Email templates
A2: Copy, fill in the [brackets], send. Week 7 is the original template from the workflow.
A4: Week | B4: Topic | C4: Subject | D4: Email
A5: Week 1 | B5: Benchmarking | C5: Week 1: where you rank right now | D5: Hi [Name], Quick update from our end. We've set everything up and run a ranking heatmap for "[main keyword]" across [area]. It shows exactly where you appear in Google Maps today, point by point across the area. That's our starting line, and we'll compare against it at the end of the 12 weeks. We also looked at the top 10 businesses ranking for this term: how many reviews and photos they have, which categories they use, and whether anyone in there shouldn't be. Next week we start on your Google Business Profile. One thing you can do straight away: ask every happy customer for a Google review. Here's your link: [review link] Talk soon, [Your name]
A6: Week 2 | B6: Starting on the GBP | C6: Week 2: working on your Google Business Profile | D6: Hi [Name], This week we started on your Google Business Profile. It's the listing that shows up in the map, and it's the biggest lever we have for local rankings. So far we've: 1) compared your profile with the top 20 businesses for "[main keyword]" 2) tightened up your categories so Google knows exactly what you do 3) started building your full list of services I'll send a list of services separately. Could you let me know which ones you DON'T do? That keeps everything on the profile accurate. Will keep you posted! [Your name]
A7: Week 2 (helper) | B7: Services check with the client | C7: Quick one: which of these services DON'T you do? | D7: Hi [Name], I'm completing the services palette for the Google Business Profile. It helps with ranking. Could you go over this list of services and let me know which services you guys DON'T do? [paste the de-duplicated services list, one per line] Thanks in advance, [Your name]
A8: Week 3 | B8: Completing the GBP | C8: Week 3: your Google profile is nearly complete | D8: Hi [Name], Quick update. We've finished most of the work on your Google Business Profile: 1) services added, with descriptions for your top 20 2) bookings link pointing to your contact page 3) FAQs added for the questions your customers ask most 4) the rest of the profile filled in so it shows as complete If you have recent photos of your work, team or premises, send them over and we'll add them. Will keep you posted! [Your name]
A9: Week 4 | B9: GBP: overview + what's next | C9: Week 4: Google profile done, here's what's next | D9: Hi [Name], Here's a summary of what we've done on your Google Business Profile this month: - Categories: [old categories] → [new categories] - Services: [x] → [y] listed, top 20 with descriptions - Bookings link and FAQs added - Profile completeness: fully green Next up is your website. Over the next four weeks we'll make sure it backs up everything the profile says: what you do, where you do it and how to reach you. Keep the reviews and photos coming, they make a real difference. [Your name]
A10: Week 5 | B10: On-page SEO: basics | C10: Week 5: website updates | D10: Hi [Name], This week we worked on the website basics that Google reads first: 1) the page title now includes your main service and [city] 2) the main heading on the homepage says what you do and where 3) your business name, address and phone number are in the footer, matching your Google profile exactly 4) your Google map is embedded on the homepage Small changes, but they give Google a much clearer signal. If the text in your browser tab looks different, that's the new title. [Your name]
A11: Week 6 | B11: On-page SEO: content structure inventory | C11: Week 6: mapping your website content | D11: Hi [Name], This week we took stock of your website: which pages Google has indexed, which services have their own page and which areas you serve that the site doesn't mention yet. Right now Google has [x] of your pages indexed. Businesses that rank well in your area usually have 30 or more. Next week we start building the pages that fill those gaps. Quick question: which 5 suburbs or towns do you get the most work from? That tells us which area pages to build first. [Your name]
A12: Week 7 | B12: On-page SEO: content structure completion | C12: Week 7: update on your website content | D12: Hi [Name], Update regarding what I mentioned last week. We've mapped out: 1) what Google has currently indexed 2) what content we'll need to add to increase topical relevance 3) what content we'll need to add to increase local relevance My team has started to put together the content we need so we can start adding that to the website and give the Google algo what it wants to improve and solidify rankings. There will be some changes on the site, nothing grand though. It's mostly us adding things in the background, giving Google more content to index so they get a clearer view of what we do and where we do it. Will keep you posted on progress!
A13: Week 8 | B13: On-page SEO: overview + what's next | C13: Week 8: website work done, citations next | D13: Hi [Name], Here's where we're at with the website: - [x] new service pages - [x] new area pages, plus an "Areas we serve" page in the menu - all pages linked together so customers and Google can find everything easily - local business schema added (code that tells Google your business details) Google now has [x] of your pages to index, up from [y]. Next we move on to citations: making sure your business is listed correctly on the sites Google trusts. Some of these send a verification code by email or phone, so I may ask you to forward one or two. [Your name]
A14: Week 9 | B14: Citations start | C14: Week 9: getting you listed in the right places | D14: Hi [Name], This week we started on citations. These are listings of your business name, address and phone number on trusted sites, and Google uses them to confirm you're a real local business. We've started with the essentials: Bing, Apple Maps, Foursquare and Yelp. You might get verification emails or calls from some of these. If you do, just forward them to me. [Your name]
A15: Week 10 | B15: Citations continued | C15: Week 10: more listings live | D15: Hi [Name], Update on citations. The core listings are [live / in verification], and we've added you to the directories that rank on Google for "[main keyword]": [list]. If Google ranks these sites for your search, it trusts them, which makes them the best places to be listed. Next week we re-run the ranking heatmap so we can compare with where we started. [Your name]
... A18: Any week | B18: Client habits reminder | C18: Two things that help your rankings most | D18: Hi [Name], Quick reminder of the two things that help your rankings most: 1) Reviews: ask every happy customer for a Google review, every time. A steady stream matters more than a big batch. Your link: [review link] 2) Photos: send me new pictures of your work, team or premises every week (or post them on Instagram / Facebook and we'll grab them). Thanks! [Your name]

Sheet Rank Log
A1: Rank log
A2: One row per heatmap run. The chart tracks average rank (lower is better) and reviews.
A4: Date | B4: Keyword | C4: Avg rank | D4: Top-3 coverage | E4: Reviews | F4: Photos | G4: Indexed pages | H4: Notes
B5: plumber springfield | C5: 14.2 | D5: 0.08 | E5: 23 | F5: 41 | G5: 9 | H5: Example row: overwrite with the baseline run

Sheet Blackhat
A1: Blackhat log
A2: We do white-hat only. Report a listing ONLY when you're 100% sure it's fake. Bad reports make Google ignore future ones.
A4: Business (as listed) | B4: GBP link | C4: Keyword-stuffed name? | D4: Implausible address? | E4: No address on website? | F4: Rented-out suspicion? | G4: Evidence (photo / video / notes) | H4: 100% sure? | I4: Reported on | J4: Method | K4: Outcome
A5: MANCHESTER TREE & STUMP REMOVALS/TREE SURGEON M4 | C5: Yes | D5: Yes (shopping mall) | E5: Yes | F5: Yes | G5: Photo of the mall interior; site shows phone only | H5: Yes | J5: Suggest an edit → Place is closed or not here | K5: Pending
A22: How to report: open the listing → Suggest an edit → 'Place is closed or not here'. Add a photo of the location and a short explanation. If it doesn't work, the client can film a walk past the address and you report again.

Sheet Prompts
A1: AI prompts
A2: Prompts from the workflow. Replace the CAPITAL / [bracketed] parts.
A4: Prompt | B4: Use it for | C4: Text
A5: Remove duplicate services | B5: Cleaning the competitor services list before adding it to the GBP | C5: I'm pasting a list of services from competitors. Your task: 1. Remove all exact duplicates 2. Remove all near-identical variants of the same term. Keep only ONE version of each — choose the most common or professional form, but do NOT edit or reword it beyond selecting one from the list. 3. Do NOT add, remove, combine, rephrase, or limit characters in any way. 4. Do NOT group, categorize, or format — just output the final clean list, one service per line, nothing else. List: [PASTE YOUR LIST HERE]
A6: Sort services into categories | B6: Only when the GBP has more than one category | C6: Sort the following services under these Google Business Profile categories: [PRIMARY CATEGORY], [SECONDARY CATEGORIES]. Put each service under exactly one category. Do not rename, add or remove services. Output each category name followed by its services, one per line. [PASTE YOUR CLEAN SERVICES LIST]
A7: Top-20 service descriptions | B7: Descriptions for the 20 most important services | C7: I need a service description for each item in the top 20. Service description has to be 300 characters or less. Business: [BUSINESS NAME], a [TYPE OF BUSINESS] in [CITY]. Top 20 services: [PASTE TOP 20]
A8: GBP FAQs | B8: FAQ section on the Google Business Profile | C8: Generate a couple of FAQ questions and answers applicable for this company, this niche, in this location. Company: [BUSINESS NAME] Niche: [TYPE OF BUSINESS] Location: [CITY / SERVICE AREA] Keep each answer short, factual and specific to the business.
A9: Title tag | B9: Homepage / GBP landing page title (Basic on-page) | C9: Write a title tag in this format, around 200 characters max: BEST + [PRIMARY CATEGORY] + [CITY] - if you're looking for [PRIMARY SERVICE] near me or [SECONDARY SERVICES] near me - [BUSINESS NAME] is the place to be Example: BEST Physiotherapist Portsmouth - if you're looking for Physiotherapy Services near me or Sports Injuries & Sports Massage near me - Hope Physiotherapy is the place to be
A10: Service page (topical authority) | B10: ADVANCED: one 1,000–2,000+ word page per service | C10: You are an experienced local SEO copywriter who specializes in <TYPE OF BUSINESS> businesses. You write engaging, trustworthy content that ranks well and actually gets read by real people. Task: Create a high-value services page (1,800–2,500 words) to build topical authority around the core topic: "WRITE THE TOPIC HERE. FOR EXAMPLE - SERVICES THAT OUR SKINCARE CLINIC IN LOCATION OFFERS". Target audience: <PUT YOUR TARGET AUDIENCE HERE>. Search intent: Primarily informational with some commercial – people want to discover the best options, different services, find top local recommendations, get practical tips. Primary keyword: "PRIMARY KEYWORD HERE" Secondary / related keywords to include naturally: IF YOU HAVE THEM, LIST SECONDARY KEYWORDS HERE. Instructions: 1. Start with a short summary of search intent and why this page will satisfy it better than competitors. 2. Build a clear, scannable outline (H1–H3) that covers the topic logically: intro → key concepts → local scene → recommendations → tips → FAQs. 3. Show expertise (E-E-A-T): Include practical insights, mention real local spots/entities, and add unique tips or a simple checklist. 4. Structure the article: - Hook + promise in the intro - Main sections with short paragraphs, bullets, numbered lists, and 1–2 small tables - Internal linking: Suggest 4–7 natural places to link to supporting pages with example anchor text - FAQ section (6–10 common questions) - Friendly conclusion + CTA (visit us, explore menu, etc.) 5. Tone: Warm, expert but approachable, conversational – like chatting with a knowledgeable expert. Human-sounding, no fluff or repetition. 6. At the end, add: - Suggested SEO title (60–120 chars) - Meta description (150–160 chars) - H1 suggestion - 3–4 image alt text ideas (local-flavored) - Brief LocalBusiness or FAQ schema outline Output format: ## Quick Strategy Summary ## Outline ## Full Article ## SEO Elements
A11: Area page (local authority) | B11: ADVANCED: one page per area served | C11: You are a senior local SEO specialist who has ranked dozens of single-location businesses in competitive cities like Amsterdam by creating hyperlocal landing pages that dominate neighborhood-specific searches. Task: Write a high-converting, SEO-optimized neighborhood landing page (1,200–2,200 words) for our <type of business> "BUSINESS NAME" located in LOCATION and serving [AREA1]. Page goal: Rank for queries like "[service] [neighborhood]", "best [service] in [neighborhood]", "[service] near [landmark]". Primary keyword: "[e.g., PRIMARY KEYWORD]" Key business facts to weave in naturally: - Physical address: [FULL NAP HERE] - Distance/proximity: - Unique selling points: [LIST ANY UNIQUE SELLING POINTS YOUR CLIENT HAS] - Local tie-ins: Mention neighborhood-specific landmarks, events, pain points Instructions: 1. First, analyze hyperlocal intent: What do searchers in this neighborhood really want? How can we prove relevance without claiming a fake address? 2. Create a scannable outline (H1–H3) that feels local-first: neighborhood intro → why we're perfect for locals here → services/products tailored to area → directions/proof → FAQs → CTA. 3. Build local authority & E-E-A-T: - Use real neighborhood references (streets, markets, events, history) - Include proximity proof + Google Maps embed suggestion - Mention local customer types/stories - Add 2025–2026 relevant local stats or trends if natural 4. Structure: - Compelling H1 + introduction with local hook - Sections on tailored offerings - "Why Locals Choose Us" with bullets or mini-testimonials - Directions + transport tips from key local spots - Embedded map + "Get Directions" CTA suggestion - 8–10 local-flavored FAQs - Strong CTA 5. On-page SEO at the end: - SEO title & meta description (hyperlocal + compelling) - Suggested schema: LocalBusiness + areaServed including neighborhood - 4–6 image alt texts with local keywords - Internal linking: 5–7 suggestions to services, menu, blog, other neighborhoods 6. Tone: Warm, community-oriented, expert but neighborly. Human, trustworthy voice — no generic corporate speak. Output format: ## Hyperlocal Intent Analysis ## Page Outline ## Full Page Content ## On-Page SEO & Schema Recommendations Note: only use real testimonials from the client. Never invent reviews or customer stories.
A12: Backlink / citation ideas | B12: ADVANCED citations | C12: Can you suggest some backlinks I could get for a <niche> in <location>?
A13: Weekly GBP update | B13: Weekly post on the Google Business Profile | C13: Write a short Google Business Profile update (under 1,000 characters) for [BUSINESS NAME], a [TYPE OF BUSINESS] in [CITY]. Topic this week: [recent job / seasonal tip / offer / FAQ]. Mention [SUBURB OR AREA] naturally, keep it friendly and specific, and end with a clear call to action (call, book or visit).
